<?xml version="1.0"?>
<robot name="jem_355_robot" xmlns:xacro="http://www.ros.org/wiki/xacro">
    <xacro:include filename="$(find jem_355_robot_description)/urdf/mobile_base_gazebo.xacro" />
    <xacro:property name="base_width" value="0.225" />
    <xacro:property name="base_length" value="0.225" />
    <xacro:property name="base_height" value="0.09" />
    <xacro:property name="wheel_radius" value="0.035" />
    <xacro:property name="wheel_length" value="0.02725" />
    <xacro:macro name="box_inertia" params="m x y z o_xyz o_rpy">
        <inertial>
            <mass value="${m}" />
            <origin xyz="${o_xyz}" rpy="${o_rpy}" />
            <inertia ixx="${(m/12) * (z*z + y*y)}" ixy="0" ixz="0"
                    iyy="${(m/12) * (x*x + z*z)}" iyz="0"
                    izz="${(m/12) * (x*x + y*y)}" />
        </inertial>
    </xacro:macro>
    <xacro:macro name="cylinder_inertia" params="m r l o_xyz o_rpy">
        <inertial>
            <mass value="${m}" />
            <origin xyz="${o_xyz}" rpy="${o_rpy}" />
            <inertia ixx="${(m/12) * (3*r*r + l*l)}" ixy="0" ixz="0"
                    iyy="${(m/12) * (3*r*r + l*l)}" iyz="0"
                    izz="${(m/2) * (r*r)}" />
        </inertial>
    </xacro:macro>
    <material name="gray">
        <color rgba="0.7 0.7 0.7 1" />
    </material>
    <material name="blue">
        <color rgba="0.5 0.5 0.9 1" />
    </material>
    <link name="base_footprint" />
    <link name="base_link">
        <visual>
            <geometry>
                <mesh filename="file://$(find jem_355_robot_description)/meshes/mobile_bot.stl" scale="0.001 0.001 0.001"/>
            </geometry>
            <origin xyz="${-base_width/2} -0.0788 0" rpy="0 0 0" />
            <material name="blue" />
        </visual>
        <collision>
            <geometry>
                <box size="${base_length} ${base_width} ${base_height}" />
            </geometry>
            <origin xyz="0 -0.047 -0.03" rpy="0 0 0" />
        </collision>
        <xacro:box_inertia m="5.0" x="${base_length}" y="${base_width}" z="${base_height}" 
                           o_xyz="0 0 ${base_height/2}" o_rpy="0 0 0" />
    </link>
    <joint name="base_link_joint" type="fixed">
        <parent link="base_footprint" />
        <child link="base_link" />
        <origin xyz="0 0 0.08" rpy="0 0 ${-pi/2}" />
    </joint>
    <xacro:macro name="wheel_link" params="prefix">
        <link name="${prefix}_wheel_link">
            <visual>
                <geometry>
                    <cylinder radius="${wheel_radius}" length="${wheel_length}" />
                </geometry>
                <origin xyz="0 0 0" rpy="${pi/2} 0 0" />
                <material name="gray" />
            </visual>
            <collision>
                <geometry>
                    <sphere radius="${wheel_radius}" />
                </geometry>
                <origin xyz="0 0 0" rpy="0 0 0" />
            </collision>
            <xacro:cylinder_inertia m="1.0" r="${wheel_radius}" l="${wheel_length}" 
                                    o_xyz="0 0 0" o_rpy="${pi / 2.0} 0 0" />
        </link>
    </xacro:macro>    
    <xacro:wheel_link prefix="right" />
    <joint name="right_wheel_joint" type="continuous">
        <parent link="base_link" />
        <child link="right_wheel_link" />
        <origin xyz="${base_width/2 + 0.014985} 0 -0.04455" rpy="0 0 ${pi/2}" />
        <axis xyz="0 1 0" />
    </joint>
    <xacro:wheel_link prefix="left" />
    <joint name="left_wheel_joint" type="continuous">
        <parent link="base_link" />
        <child link="left_wheel_link" />
        <origin xyz="-${base_width/2 + 0.014985} 0 -0.04455" rpy="0 0 ${pi/2}" />
        <axis xyz="0 1 0" />
    </joint>
</robot>